[2025-04-03T21:44:24.327+0000] {local_task_job_runner.py:123} INFO - ::group::Pre task execution logs
[2025-04-03T21:44:24.344+0000] {taskinstance.py:2614} INFO - Dependencies all met for dep_context=non-requeueable deps ti=<TaskInstance: executar_script_windows_ssh.rodar_script_via_ssh manual__2025-04-03T21:44:23.476623+00:00 [queued]>
[2025-04-03T21:44:24.351+0000] {taskinstance.py:2614} INFO - Dependencies all met for dep_context=requeueable deps ti=<TaskInstance: executar_script_windows_ssh.rodar_script_via_ssh manual__2025-04-03T21:44:23.476623+00:00 [queued]>
[2025-04-03T21:44:24.352+0000] {taskinstance.py:2867} INFO - Starting attempt 1 of 1
[2025-04-03T21:44:24.364+0000] {taskinstance.py:2890} INFO - Executing <Task(SSHOperator): rodar_script_via_ssh> on 2025-04-03 21:44:23.476623+00:00
[2025-04-03T21:44:24.372+0000] {standard_task_runner.py:104} INFO - Running: ['***', 'tasks', 'run', 'executar_script_windows_ssh', 'rodar_script_via_ssh', 'manual__2025-04-03T21:44:23.476623+00:00', '--job-id', '5', '--raw', '--subdir', 'DAGS_FOLDER/dag_scraping.py', '--cfg-path', '/tmp/tmpni6f6fjv']
[2025-04-03T21:44:24.373+0000] {standard_task_runner.py:105} INFO - Job 5: Subtask rodar_script_via_ssh
[2025-04-03T21:44:24.377+0000] {warnings.py:112} WARNING - /home/***/.local/lib/python3.12/site-packages/***/task/task_runner/standard_task_runner.py:70: DeprecationWarning: This process (pid=62) is multi-threaded, use of fork() may lead to deadlocks in the child.
  pid = os.fork()

[2025-04-03T21:44:24.385+0000] {standard_task_runner.py:72} INFO - Started process 63 to run task
[2025-04-03T21:44:24.469+0000] {task_command.py:467} INFO - Running <TaskInstance: executar_script_windows_ssh.rodar_script_via_ssh manual__2025-04-03T21:44:23.476623+00:00 [running]> on host 87592eb49ea7
[2025-04-03T21:44:24.648+0000] {taskinstance.py:3134} INFO - Exporting env vars: AIRFLOW_CTX_DAG_OWNER='***' AIRFLOW_CTX_DAG_ID='executar_script_windows_ssh' AIRFLOW_CTX_TASK_ID='rodar_script_via_ssh' AIRFLOW_CTX_EXECUTION_DATE='2025-04-03T21:44:23.476623+00:00' AIRFLOW_CTX_TRY_NUMBER='1' AIRFLOW_CTX_DAG_RUN_ID='manual__2025-04-03T21:44:23.476623+00:00'
[2025-04-03T21:44:24.648+0000] {taskinstance.py:732} INFO - ::endgroup::
[2025-04-03T21:44:24.661+0000] {ssh.py:123} INFO - ssh_hook is not provided or invalid. Trying ssh_conn_id to create SSHHook.
[2025-04-03T21:44:24.679+0000] {base.py:84} INFO - Retrieving connection 'windows_ssh'
[2025-04-03T21:44:24.680+0000] {ssh.py:286} WARNING - No Host Key Verification. This won't protect against Man-In-The-Middle attacks
[2025-04-03T21:44:24.712+0000] {transport.py:1944} INFO - Connected (version 2.0, client OpenSSH_for_Windows_9.5)
[2025-04-03T21:44:24.865+0000] {transport.py:1944} INFO - Authentication (password) failed.
[2025-04-03T21:44:24.866+0000] {ssh.py:329} INFO - Failed to connect. Sleeping before retry attempt 1
[2025-04-03T21:44:28.651+0000] {transport.py:1944} INFO - Connected (version 2.0, client OpenSSH_for_Windows_9.5)
[2025-04-03T21:44:28.691+0000] {transport.py:1944} INFO - Authentication (password) failed.
[2025-04-03T21:44:28.693+0000] {ssh.py:329} INFO - Failed to connect. Sleeping before retry attempt 2
[2025-04-03T21:44:32.599+0000] {transport.py:1944} INFO - Connected (version 2.0, client OpenSSH_for_Windows_9.5)
[2025-04-03T21:44:32.637+0000] {transport.py:1944} INFO - Authentication (password) failed.
[2025-04-03T21:44:32.638+0000] {taskinstance.py:3313} ERROR - Task failed with exception
Traceback (most recent call last):
  File "/home/airflow/.local/lib/python3.12/site-packages/airflow/models/taskinstance.py", line 768, in _execute_task
    result = _execute_callable(context=context, **execute_callable_kwargs)
             ^^^^^^^^^^^^^^^^^^^^^^^^^^^^^^^^^^^^^^^^^^^^^^^^^^^^^^^^^^^^^
  File "/home/airflow/.local/lib/python3.12/site-packages/airflow/models/taskinstance.py", line 734, in _execute_callable
    return ExecutionCallableRunner(
           ^^^^^^^^^^^^^^^^^^^^^^^^
  File "/home/airflow/.local/lib/python3.12/site-packages/airflow/utils/operator_helpers.py", line 252, in run
    return self.func(*args, **kwargs)
           ^^^^^^^^^^^^^^^^^^^^^^^^^^
  File "/home/airflow/.local/lib/python3.12/site-packages/airflow/models/baseoperator.py", line 424, in wrapper
    return func(self, *args, **kwargs)
           ^^^^^^^^^^^^^^^^^^^^^^^^^^^
  File "/home/airflow/.local/lib/python3.12/site-packages/airflow/providers/ssh/operators/ssh.py", line 172, in execute
    with self.get_ssh_client() as ssh_client:
         ^^^^^^^^^^^^^^^^^^^^^
  File "/home/airflow/.local/lib/python3.12/site-packages/airflow/providers/ssh/operators/ssh.py", line 146, in get_ssh_client
    return self.hook.get_conn()
           ^^^^^^^^^^^^^^^^^^^^
  File "/home/airflow/.local/lib/python3.12/site-packages/airflow/providers/ssh/hooks/ssh.py", line 333, in get_conn
    for attempt in Retrying(
                   ^^^^^^^^^
  File "/home/airflow/.local/lib/python3.12/site-packages/tenacity/__init__.py", line 443, in __iter__
    do = self.iter(retry_state=retry_state)
         ^^^^^^^^^^^^^^^^^^^^^^^^^^^^^^^^^^
  File "/home/airflow/.local/lib/python3.12/site-packages/tenacity/__init__.py", line 376, in iter
    result = action(retry_state)
             ^^^^^^^^^^^^^^^^^^^
  File "/home/airflow/.local/lib/python3.12/site-packages/tenacity/__init__.py", line 418, in exc_check
    raise retry_exc.reraise()
          ^^^^^^^^^^^^^^^^^^^
  File "/home/airflow/.local/lib/python3.12/site-packages/tenacity/__init__.py", line 185, in reraise
    raise self.last_attempt.result()
          ^^^^^^^^^^^^^^^^^^^^^^^^^^
  File "/usr/local/lib/python3.12/concurrent/futures/_base.py", line 449, in result
    return self.__get_result()
           ^^^^^^^^^^^^^^^^^^^
  File "/usr/local/lib/python3.12/concurrent/futures/_base.py", line 401, in __get_result
    raise self._exception
  File "/home/airflow/.local/lib/python3.12/site-packages/airflow/providers/ssh/hooks/ssh.py", line 340, in get_conn
    client.connect(**connect_kwargs)
  File "/home/airflow/.local/lib/python3.12/site-packages/paramiko/client.py", line 485, in connect
    self._auth(
  File "/home/airflow/.local/lib/python3.12/site-packages/paramiko/client.py", line 818, in _auth
    raise saved_exception
  File "/home/airflow/.local/lib/python3.12/site-packages/paramiko/client.py", line 805, in _auth
    self._transport.auth_password(username, password)
  File "/home/airflow/.local/lib/python3.12/site-packages/paramiko/transport.py", line 1638, in auth_password
    return self.auth_handler.wait_for_response(my_event)
           ^^^^^^^^^^^^^^^^^^^^^^^^^^^^^^^^^^^^^^^^^^^^^
  File "/home/airflow/.local/lib/python3.12/site-packages/paramiko/auth_handler.py", line 263, in wait_for_response
    raise e
paramiko.ssh_exception.AuthenticationException: Authentication failed.
[2025-04-03T21:44:32.664+0000] {taskinstance.py:1226} INFO - Marking task as FAILED. dag_id=executar_script_windows_ssh, task_id=rodar_script_via_ssh, run_id=manual__2025-04-03T21:44:23.476623+00:00, execution_date=20250403T214423, start_date=20250403T214424, end_date=20250403T214432
[2025-04-03T21:44:32.705+0000] {taskinstance.py:341} INFO - ::group::Post task execution logs
[2025-04-03T21:44:32.705+0000] {standard_task_runner.py:124} ERROR - Failed to execute job 5 for task rodar_script_via_ssh (Authentication failed.; 63)
Traceback (most recent call last):
  File "/home/airflow/.local/lib/python3.12/site-packages/airflow/task/task_runner/standard_task_runner.py", line 117, in _start_by_fork
    ret = args.func(args, dag=self.dag)
          ^^^^^^^^^^^^^^^^^^^^^^^^^^^^^
  File "/home/airflow/.local/lib/python3.12/site-packages/airflow/cli/cli_config.py", line 49, in command
    return func(*args, **kwargs)
           ^^^^^^^^^^^^^^^^^^^^^
  File "/home/airflow/.local/lib/python3.12/site-packages/airflow/utils/cli.py", line 116, in wrapper
    return f(*args, **kwargs)
           ^^^^^^^^^^^^^^^^^^
  File "/home/airflow/.local/lib/python3.12/site-packages/airflow/cli/commands/task_command.py", line 483, in task_run
    task_return_code = _run_task_by_selected_method(args, _dag, ti)
                       ^^^^^^^^^^^^^^^^^^^^^^^^^^^^^^^^^^^^^^^^^^^^
  File "/home/airflow/.local/lib/python3.12/site-packages/airflow/cli/commands/task_command.py", line 256, in _run_task_by_selected_method
    return _run_raw_task(args, ti)
           ^^^^^^^^^^^^^^^^^^^^^^^
  File "/home/airflow/.local/lib/python3.12/site-packages/airflow/cli/commands/task_command.py", line 341, in _run_raw_task
    return ti._run_raw_task(
           ^^^^^^^^^^^^^^^^^
  File "/home/airflow/.local/lib/python3.12/site-packages/airflow/utils/session.py", line 97, in wrapper
    return func(*args, session=session, **kwargs)
           ^^^^^^^^^^^^^^^^^^^^^^^^^^^^^^^^^^^^^^
  File "/home/airflow/.local/lib/python3.12/site-packages/airflow/models/taskinstance.py", line 3006, in _run_raw_task
    return _run_raw_task(
           ^^^^^^^^^^^^^^
  File "/home/airflow/.local/lib/python3.12/site-packages/airflow/models/taskinstance.py", line 274, in _run_raw_task
    TaskInstance._execute_task_with_callbacks(
  File "/home/airflow/.local/lib/python3.12/site-packages/airflow/models/taskinstance.py", line 3161, in _execute_task_with_callbacks
    result = self._execute_task(context, task_orig)
             ^^^^^^^^^^^^^^^^^^^^^^^^^^^^^^^^^^^^^^
  File "/home/airflow/.local/lib/python3.12/site-packages/airflow/models/taskinstance.py", line 3185, in _execute_task
    return _execute_task(self, context, task_orig)
           ^^^^^^^^^^^^^^^^^^^^^^^^^^^^^^^^^^^^^^^
  File "/home/airflow/.local/lib/python3.12/site-packages/airflow/models/taskinstance.py", line 768, in _execute_task
    result = _execute_callable(context=context, **execute_callable_kwargs)
             ^^^^^^^^^^^^^^^^^^^^^^^^^^^^^^^^^^^^^^^^^^^^^^^^^^^^^^^^^^^^^
  File "/home/airflow/.local/lib/python3.12/site-packages/airflow/models/taskinstance.py", line 734, in _execute_callable
    return ExecutionCallableRunner(
           ^^^^^^^^^^^^^^^^^^^^^^^^
  File "/home/airflow/.local/lib/python3.12/site-packages/airflow/utils/operator_helpers.py", line 252, in run
    return self.func(*args, **kwargs)
           ^^^^^^^^^^^^^^^^^^^^^^^^^^
  File "/home/airflow/.local/lib/python3.12/site-packages/airflow/models/baseoperator.py", line 424, in wrapper
    return func(self, *args, **kwargs)
           ^^^^^^^^^^^^^^^^^^^^^^^^^^^
  File "/home/airflow/.local/lib/python3.12/site-packages/airflow/providers/ssh/operators/ssh.py", line 172, in execute
    with self.get_ssh_client() as ssh_client:
         ^^^^^^^^^^^^^^^^^^^^^
  File "/home/airflow/.local/lib/python3.12/site-packages/airflow/providers/ssh/operators/ssh.py", line 146, in get_ssh_client
    return self.hook.get_conn()
           ^^^^^^^^^^^^^^^^^^^^
  File "/home/airflow/.local/lib/python3.12/site-packages/airflow/providers/ssh/hooks/ssh.py", line 333, in get_conn
    for attempt in Retrying(
                   ^^^^^^^^^
  File "/home/airflow/.local/lib/python3.12/site-packages/tenacity/__init__.py", line 443, in __iter__
    do = self.iter(retry_state=retry_state)
         ^^^^^^^^^^^^^^^^^^^^^^^^^^^^^^^^^^
  File "/home/airflow/.local/lib/python3.12/site-packages/tenacity/__init__.py", line 376, in iter
    result = action(retry_state)
             ^^^^^^^^^^^^^^^^^^^
  File "/home/airflow/.local/lib/python3.12/site-packages/tenacity/__init__.py", line 418, in exc_check
    raise retry_exc.reraise()
          ^^^^^^^^^^^^^^^^^^^
  File "/home/airflow/.local/lib/python3.12/site-packages/tenacity/__init__.py", line 185, in reraise
    raise self.last_attempt.result()
          ^^^^^^^^^^^^^^^^^^^^^^^^^^
  File "/usr/local/lib/python3.12/concurrent/futures/_base.py", line 449, in result
    return self.__get_result()
           ^^^^^^^^^^^^^^^^^^^
  File "/usr/local/lib/python3.12/concurrent/futures/_base.py", line 401, in __get_result
    raise self._exception
  File "/home/airflow/.local/lib/python3.12/site-packages/airflow/providers/ssh/hooks/ssh.py", line 340, in get_conn
    client.connect(**connect_kwargs)
  File "/home/airflow/.local/lib/python3.12/site-packages/paramiko/client.py", line 485, in connect
    self._auth(
  File "/home/airflow/.local/lib/python3.12/site-packages/paramiko/client.py", line 818, in _auth
    raise saved_exception
  File "/home/airflow/.local/lib/python3.12/site-packages/paramiko/client.py", line 805, in _auth
    self._transport.auth_password(username, password)
  File "/home/airflow/.local/lib/python3.12/site-packages/paramiko/transport.py", line 1638, in auth_password
    return self.auth_handler.wait_for_response(my_event)
           ^^^^^^^^^^^^^^^^^^^^^^^^^^^^^^^^^^^^^^^^^^^^^
  File "/home/airflow/.local/lib/python3.12/site-packages/paramiko/auth_handler.py", line 263, in wait_for_response
    raise e
paramiko.ssh_exception.AuthenticationException: Authentication failed.
[2025-04-03T21:44:32.738+0000] {local_task_job_runner.py:266} INFO - Task exited with return code 1
[2025-04-03T21:44:32.751+0000] {taskinstance.py:3901} INFO - 0 downstream tasks scheduled from follow-on schedule check
[2025-04-03T21:44:32.755+0000] {local_task_job_runner.py:245} INFO - ::endgroup::
