[2025-04-03T21:40:43.819+0000] {local_task_job_runner.py:123} INFO - ::group::Pre task execution logs
[2025-04-03T21:40:43.836+0000] {taskinstance.py:2614} INFO - Dependencies all met for dep_context=non-requeueable deps ti=<TaskInstance: executar_script_windows_ssh.rodar_script_via_ssh manual__2025-04-03T21:40:43.258547+00:00 [queued]>
[2025-04-03T21:40:43.842+0000] {taskinstance.py:2614} INFO - Dependencies all met for dep_context=requeueable deps ti=<TaskInstance: executar_script_windows_ssh.rodar_script_via_ssh manual__2025-04-03T21:40:43.258547+00:00 [queued]>
[2025-04-03T21:40:43.842+0000] {taskinstance.py:2867} INFO - Starting attempt 1 of 1
[2025-04-03T21:40:43.855+0000] {taskinstance.py:2890} INFO - Executing <Task(SSHOperator): rodar_script_via_ssh> on 2025-04-03 21:40:43.258547+00:00
[2025-04-03T21:40:43.863+0000] {warnings.py:112} WARNING - /home/***/.local/lib/python3.12/site-packages/***/task/task_runner/standard_task_runner.py:70: DeprecationWarning: This process (pid=59) is multi-threaded, use of fork() may lead to deadlocks in the child.
  pid = os.fork()

[2025-04-03T21:40:43.865+0000] {standard_task_runner.py:72} INFO - Started process 60 to run task
[2025-04-03T21:40:43.865+0000] {standard_task_runner.py:104} INFO - Running: ['***', 'tasks', 'run', 'executar_script_windows_ssh', 'rodar_script_via_ssh', 'manual__2025-04-03T21:40:43.258547+00:00', '--job-id', '4', '--raw', '--subdir', 'DAGS_FOLDER/dag_scraping.py', '--cfg-path', '/tmp/tmpnvopnl9w']
[2025-04-03T21:40:43.866+0000] {standard_task_runner.py:105} INFO - Job 4: Subtask rodar_script_via_ssh
[2025-04-03T21:40:43.928+0000] {task_command.py:467} INFO - Running <TaskInstance: executar_script_windows_ssh.rodar_script_via_ssh manual__2025-04-03T21:40:43.258547+00:00 [running]> on host 87592eb49ea7
[2025-04-03T21:40:44.010+0000] {taskinstance.py:3134} INFO - Exporting env vars: AIRFLOW_CTX_DAG_OWNER='***' AIRFLOW_CTX_DAG_ID='executar_script_windows_ssh' AIRFLOW_CTX_TASK_ID='rodar_script_via_ssh' AIRFLOW_CTX_EXECUTION_DATE='2025-04-03T21:40:43.258547+00:00' AIRFLOW_CTX_TRY_NUMBER='1' AIRFLOW_CTX_DAG_RUN_ID='manual__2025-04-03T21:40:43.258547+00:00'
[2025-04-03T21:40:44.012+0000] {taskinstance.py:732} INFO - ::endgroup::
[2025-04-03T21:40:44.026+0000] {ssh.py:123} INFO - ssh_hook is not provided or invalid. Trying ssh_conn_id to create SSHHook.
[2025-04-03T21:40:44.035+0000] {base.py:84} INFO - Retrieving connection 'windows_ssh'
[2025-04-03T21:40:44.036+0000] {ssh.py:286} WARNING - No Host Key Verification. This won't protect against Man-In-The-Middle attacks
[2025-04-03T21:40:45.872+0000] {ssh.py:329} INFO - Failed to connect. Sleeping before retry attempt 1
[2025-04-03T21:40:51.088+0000] {ssh.py:329} INFO - Failed to connect. Sleeping before retry attempt 2
[2025-04-03T21:40:56.129+0000] {taskinstance.py:3313} ERROR - Task failed with exception
Traceback (most recent call last):
  File "/home/airflow/.local/lib/python3.12/site-packages/airflow/models/taskinstance.py", line 768, in _execute_task
    result = _execute_callable(context=context, **execute_callable_kwargs)
             ^^^^^^^^^^^^^^^^^^^^^^^^^^^^^^^^^^^^^^^^^^^^^^^^^^^^^^^^^^^^^
  File "/home/airflow/.local/lib/python3.12/site-packages/airflow/models/taskinstance.py", line 734, in _execute_callable
    return ExecutionCallableRunner(
           ^^^^^^^^^^^^^^^^^^^^^^^^
  File "/home/airflow/.local/lib/python3.12/site-packages/airflow/utils/operator_helpers.py", line 252, in run
    return self.func(*args, **kwargs)
           ^^^^^^^^^^^^^^^^^^^^^^^^^^
  File "/home/airflow/.local/lib/python3.12/site-packages/airflow/models/baseoperator.py", line 424, in wrapper
    return func(self, *args, **kwargs)
           ^^^^^^^^^^^^^^^^^^^^^^^^^^^
  File "/home/airflow/.local/lib/python3.12/site-packages/airflow/providers/ssh/operators/ssh.py", line 172, in execute
    with self.get_ssh_client() as ssh_client:
         ^^^^^^^^^^^^^^^^^^^^^
  File "/home/airflow/.local/lib/python3.12/site-packages/airflow/providers/ssh/operators/ssh.py", line 146, in get_ssh_client
    return self.hook.get_conn()
           ^^^^^^^^^^^^^^^^^^^^
  File "/home/airflow/.local/lib/python3.12/site-packages/airflow/providers/ssh/hooks/ssh.py", line 333, in get_conn
    for attempt in Retrying(
                   ^^^^^^^^^
  File "/home/airflow/.local/lib/python3.12/site-packages/tenacity/__init__.py", line 443, in __iter__
    do = self.iter(retry_state=retry_state)
         ^^^^^^^^^^^^^^^^^^^^^^^^^^^^^^^^^^
  File "/home/airflow/.local/lib/python3.12/site-packages/tenacity/__init__.py", line 376, in iter
    result = action(retry_state)
             ^^^^^^^^^^^^^^^^^^^
  File "/home/airflow/.local/lib/python3.12/site-packages/tenacity/__init__.py", line 418, in exc_check
    raise retry_exc.reraise()
          ^^^^^^^^^^^^^^^^^^^
  File "/home/airflow/.local/lib/python3.12/site-packages/tenacity/__init__.py", line 185, in reraise
    raise self.last_attempt.result()
          ^^^^^^^^^^^^^^^^^^^^^^^^^^
  File "/usr/local/lib/python3.12/concurrent/futures/_base.py", line 449, in result
    return self.__get_result()
           ^^^^^^^^^^^^^^^^^^^
  File "/usr/local/lib/python3.12/concurrent/futures/_base.py", line 401, in __get_result
    raise self._exception
  File "/home/airflow/.local/lib/python3.12/site-packages/airflow/providers/ssh/hooks/ssh.py", line 340, in get_conn
    client.connect(**connect_kwargs)
  File "/home/airflow/.local/lib/python3.12/site-packages/paramiko/client.py", line 409, in connect
    raise NoValidConnectionsError(errors)
paramiko.ssh_exception.NoValidConnectionsError: [Errno None] Unable to connect to port 22 on 192.168.15.10
[2025-04-03T21:40:56.139+0000] {taskinstance.py:1226} INFO - Marking task as FAILED. dag_id=executar_script_windows_ssh, task_id=rodar_script_via_ssh, run_id=manual__2025-04-03T21:40:43.258547+00:00, execution_date=20250403T214043, start_date=20250403T214043, end_date=20250403T214056
[2025-04-03T21:40:56.165+0000] {taskinstance.py:341} INFO - ::group::Post task execution logs
[2025-04-03T21:40:56.166+0000] {standard_task_runner.py:124} ERROR - Failed to execute job 4 for task rodar_script_via_ssh ([Errno None] Unable to connect to port 22 on 192.168.15.10; 60)
Traceback (most recent call last):
  File "/home/airflow/.local/lib/python3.12/site-packages/airflow/task/task_runner/standard_task_runner.py", line 117, in _start_by_fork
    ret = args.func(args, dag=self.dag)
          ^^^^^^^^^^^^^^^^^^^^^^^^^^^^^
  File "/home/airflow/.local/lib/python3.12/site-packages/airflow/cli/cli_config.py", line 49, in command
    return func(*args, **kwargs)
           ^^^^^^^^^^^^^^^^^^^^^
  File "/home/airflow/.local/lib/python3.12/site-packages/airflow/utils/cli.py", line 116, in wrapper
    return f(*args, **kwargs)
           ^^^^^^^^^^^^^^^^^^
  File "/home/airflow/.local/lib/python3.12/site-packages/airflow/cli/commands/task_command.py", line 483, in task_run
    task_return_code = _run_task_by_selected_method(args, _dag, ti)
                       ^^^^^^^^^^^^^^^^^^^^^^^^^^^^^^^^^^^^^^^^^^^^
  File "/home/airflow/.local/lib/python3.12/site-packages/airflow/cli/commands/task_command.py", line 256, in _run_task_by_selected_method
    return _run_raw_task(args, ti)
           ^^^^^^^^^^^^^^^^^^^^^^^
  File "/home/airflow/.local/lib/python3.12/site-packages/airflow/cli/commands/task_command.py", line 341, in _run_raw_task
    return ti._run_raw_task(
           ^^^^^^^^^^^^^^^^^
  File "/home/airflow/.local/lib/python3.12/site-packages/airflow/utils/session.py", line 97, in wrapper
    return func(*args, session=session, **kwargs)
           ^^^^^^^^^^^^^^^^^^^^^^^^^^^^^^^^^^^^^^
  File "/home/airflow/.local/lib/python3.12/site-packages/airflow/models/taskinstance.py", line 3006, in _run_raw_task
    return _run_raw_task(
           ^^^^^^^^^^^^^^
  File "/home/airflow/.local/lib/python3.12/site-packages/airflow/models/taskinstance.py", line 274, in _run_raw_task
    TaskInstance._execute_task_with_callbacks(
  File "/home/airflow/.local/lib/python3.12/site-packages/airflow/models/taskinstance.py", line 3161, in _execute_task_with_callbacks
    result = self._execute_task(context, task_orig)
             ^^^^^^^^^^^^^^^^^^^^^^^^^^^^^^^^^^^^^^
  File "/home/airflow/.local/lib/python3.12/site-packages/airflow/models/taskinstance.py", line 3185, in _execute_task
    return _execute_task(self, context, task_orig)
           ^^^^^^^^^^^^^^^^^^^^^^^^^^^^^^^^^^^^^^^
  File "/home/airflow/.local/lib/python3.12/site-packages/airflow/models/taskinstance.py", line 768, in _execute_task
    result = _execute_callable(context=context, **execute_callable_kwargs)
             ^^^^^^^^^^^^^^^^^^^^^^^^^^^^^^^^^^^^^^^^^^^^^^^^^^^^^^^^^^^^^
  File "/home/airflow/.local/lib/python3.12/site-packages/airflow/models/taskinstance.py", line 734, in _execute_callable
    return ExecutionCallableRunner(
           ^^^^^^^^^^^^^^^^^^^^^^^^
  File "/home/airflow/.local/lib/python3.12/site-packages/airflow/utils/operator_helpers.py", line 252, in run
    return self.func(*args, **kwargs)
           ^^^^^^^^^^^^^^^^^^^^^^^^^^
  File "/home/airflow/.local/lib/python3.12/site-packages/airflow/models/baseoperator.py", line 424, in wrapper
    return func(self, *args, **kwargs)
           ^^^^^^^^^^^^^^^^^^^^^^^^^^^
  File "/home/airflow/.local/lib/python3.12/site-packages/airflow/providers/ssh/operators/ssh.py", line 172, in execute
    with self.get_ssh_client() as ssh_client:
         ^^^^^^^^^^^^^^^^^^^^^
  File "/home/airflow/.local/lib/python3.12/site-packages/airflow/providers/ssh/operators/ssh.py", line 146, in get_ssh_client
    return self.hook.get_conn()
           ^^^^^^^^^^^^^^^^^^^^
  File "/home/airflow/.local/lib/python3.12/site-packages/airflow/providers/ssh/hooks/ssh.py", line 333, in get_conn
    for attempt in Retrying(
                   ^^^^^^^^^
  File "/home/airflow/.local/lib/python3.12/site-packages/tenacity/__init__.py", line 443, in __iter__
    do = self.iter(retry_state=retry_state)
         ^^^^^^^^^^^^^^^^^^^^^^^^^^^^^^^^^^
  File "/home/airflow/.local/lib/python3.12/site-packages/tenacity/__init__.py", line 376, in iter
    result = action(retry_state)
             ^^^^^^^^^^^^^^^^^^^
  File "/home/airflow/.local/lib/python3.12/site-packages/tenacity/__init__.py", line 418, in exc_check
    raise retry_exc.reraise()
          ^^^^^^^^^^^^^^^^^^^
  File "/home/airflow/.local/lib/python3.12/site-packages/tenacity/__init__.py", line 185, in reraise
    raise self.last_attempt.result()
          ^^^^^^^^^^^^^^^^^^^^^^^^^^
  File "/usr/local/lib/python3.12/concurrent/futures/_base.py", line 449, in result
    return self.__get_result()
           ^^^^^^^^^^^^^^^^^^^
  File "/usr/local/lib/python3.12/concurrent/futures/_base.py", line 401, in __get_result
    raise self._exception
  File "/home/airflow/.local/lib/python3.12/site-packages/airflow/providers/ssh/hooks/ssh.py", line 340, in get_conn
    client.connect(**connect_kwargs)
  File "/home/airflow/.local/lib/python3.12/site-packages/paramiko/client.py", line 409, in connect
    raise NoValidConnectionsError(errors)
paramiko.ssh_exception.NoValidConnectionsError: [Errno None] Unable to connect to port 22 on 192.168.15.10
[2025-04-03T21:40:56.208+0000] {local_task_job_runner.py:266} INFO - Task exited with return code 1
[2025-04-03T21:40:56.219+0000] {taskinstance.py:3901} INFO - 0 downstream tasks scheduled from follow-on schedule check
[2025-04-03T21:40:56.223+0000] {local_task_job_runner.py:245} INFO - ::endgroup::
